<?xml version="1.0" ?>
<robot name="turtlebot3_burger"
  xmlns:xacro="http://ros.org/wiki/xacro">
  <!-- <xacro:include filename="$(find turtlebot)/urdf/common_properties.urdf"/> -->

  <xacro:arg name="namespace" default=""/>
  <xacro:property name="namespace" value="$(arg namespace)"/>

  <!-- Init colour -->
  <material name="black">
      <color rgba="0.0 0.0 0.0 1.0"/>
  </material>

  <material name="dark">
    <color rgba="0.3 0.3 0.3 1.0"/>
  </material>

  <material name="light_black">
    <color rgba="0.4 0.4 0.4 1.0"/>
  </material>

  <material name="blue">
    <color rgba="0.0 0.0 0.8 1.0"/>
  </material>

  <material name="green">
    <color rgba="0.0 0.8 0.0 1.0"/>
  </material>

  <material name="grey">
    <color rgba="0.5 0.5 0.5 1.0"/>
  </material>

  <material name="orange">
    <color rgba="1.0 0.4235 0.0392 1.0"/>
  </material>

  <material name="brown">
    <color rgba="0.8706 0.8118 0.7647 1.0"/>
  </material>

  <material name="red">
    <color rgba="0.8 0.0 0.0 1.0"/>
  </material>

  <material name="white">
    <color rgba="1.0 1.0 1.0 1.0"/>
  </material>

  <link name="${namespace}base_footprint"/>

  <joint name="${namespace}base_joint" type="fixed">
    <parent link="${namespace}base_footprint"/>
    <child link="${namespace}base_link"/>
    <origin xyz="0.0 0.0 0.010" rpy="0 0 0"/>
  </joint>

  <link name="${namespace}base_link">
    <visual>
      <origin xyz="-0.032 0 0.0" rpy="0 0 0"/>
      <geometry>
        <mesh filename="file://$(find turtlebot)/meshes/burger_base.stl" scale="0.001 0.001 0.001"/>
      </geometry>
      <material name="light_black"/>
    </visual>

    <collision>
      <origin xyz="-0.032 0 0.070" rpy="0 0 0"/>
      <geometry>
        <box size="0.140 0.140 0.143"/>
      </geometry>
    </collision>

    <inertial>
      <origin xyz="0 0 0" rpy="0 0 0"/>
      <mass value="8.2573504e-01"/>
      <inertia ixx="2.2124416e-03" ixy="-1.2294101e-05" ixz="3.4938785e-05" iyy="2.1193702e-03" iyz="-5.0120904e-06" izz="2.0064271e-03" />
    </inertial>
  </link>

  <joint name="${namespace}wheel_left_joint" type="continuous">
    <parent link="${namespace}base_link"/>
    <child link="${namespace}wheel_left_link"/>
    <origin xyz="0.0 0.08 0.023" rpy="-1.57 0 0"/>
    <axis xyz="0 0 1"/>
  </joint>

  <link name="${namespace}wheel_left_link">
    <visual>
      <origin xyz="0 0 0" rpy="1.57 0 0"/>
      <geometry>
        <mesh filename="file://$(find turtlebot)/meshes/left_tire.stl" scale="0.001 0.001 0.001"/>
      </geometry>
      <material name="dark"/>
    </visual>

    <collision>
      <origin xyz="0 0 0" rpy="0 0 0"/>
      <geometry>
        <cylinder length="0.018" radius="0.033"/>
      </geometry>
    </collision>

    <inertial>
      <origin xyz="0 0 0" />
      <mass value="2.8498940e-02" />
      <inertia ixx="1.1175580e-05" ixy="-4.2369783e-11" ixz="-5.9381719e-09" iyy="1.1192413e-05" iyz="-1.4400107e-11" izz="2.0712558e-05" />
    </inertial>
  </link>

  <joint name="${namespace}wheel_right_joint" type="continuous">
    <parent link="${namespace}base_link"/>
    <child link="${namespace}wheel_right_link"/>
    <origin xyz="0.0 -0.080 0.023" rpy="-1.57 0 0"/>
    <axis xyz="0 0 1"/>
  </joint>

  <link name="${namespace}wheel_right_link">
    <visual>
      <origin xyz="0 0 0" rpy="1.57 0 0"/>
      <geometry>
        <mesh filename="file://$(find turtlebot)/meshes/right_tire.stl" scale="0.001 0.001 0.001"/>
      </geometry>
      <material name="dark"/>
    </visual>

    <collision>
      <origin xyz="0 0 0" rpy="0 0 0"/>
      <geometry>
        <cylinder length="0.018" radius="0.033"/>
      </geometry>
    </collision>

    <inertial>
      <origin xyz="0 0 0" />
      <mass value="2.8498940e-02" />
      <inertia ixx="1.1175580e-05" ixy="-4.2369783e-11" ixz="-5.9381719e-09" iyy="1.1192413e-05" iyz="-1.4400107e-11" izz="2.0712558e-05" />
    </inertial>
  </link>

  <joint name="${namespace}caster_back_joint" type="fixed">
    <parent link="${namespace}base_link"/>
    <child link="${namespace}caster_back_link"/>
    <origin xyz="-0.081 0 -0.004" rpy="-1.57 0 0"/>
  </joint>

  <link name="${namespace}caster_back_link">
    <collision>
      <origin xyz="0 0.001 0" rpy="0 0 0"/>
      <geometry>
        <box size="0.030 0.009 0.020"/>
      </geometry>
    </collision>

    <inertial>
      <origin xyz="0 0 0" />
      <mass value="0.005" />
      <inertia ixx="0.001" ixy="0.0" ixz="0.0" iyy="0.001" iyz="0.0" izz="0.001" />
    </inertial>
  </link>

  <joint name="${namespace}imu_joint" type="fixed">
    <parent link="${namespace}base_link"/>
    <child link="${namespace}imu_link"/>
    <origin xyz="-0.032 0 0.068" rpy="0 0 0"/>
  </joint>

  <link name="${namespace}imu_link"/>

  <joint name="${namespace}scan_joint" type="fixed">
    <parent link="${namespace}base_link"/>
    <child link="${namespace}base_scan"/>
    <origin xyz="-0.032 0 0.172" rpy="0 0 0"/>
  </joint>

  <link name="${namespace}base_scan">
    <visual>
      <origin xyz="0 0 0.0" rpy="0 0 0"/>
      <geometry>
        <mesh filename="file://$(find turtlebot)/meshes/lds.stl" scale="0.001 0.001 0.001"/>
      </geometry>
      <material name="dark"/>
    </visual>

    <collision>
      <origin xyz="0.015 0 -0.0065" rpy="0 0 0"/>
      <geometry>
        <cylinder length="0.0315" radius="0.055"/>
      </geometry>
    </collision>

    <inertial>
      <mass value="0.114" />
      <origin xyz="0 0 0" />
      <inertia ixx="0.001" ixy="0.0" ixz="0.0" iyy="0.001" iyz="0.0" izz="0.001" />
    </inertial>
  </link>
<gazebo>
        <plugin name="ignition::gazebo::systems::DiffDrive" filename="ignition-gazebo-diff-drive-system"> 
            <num_wheel_pairs>1</num_wheel_pairs>
            <!-- Wheel Information -->
            
            <left_joint>${namespace}wheel_left_joint</left_joint>
            <right_joint>${namespace}wheel_right_joint</right_joint>
            
            <wheel_separation>0.16</wheel_separation>
            <wheel_radius>0.033</wheel_radius>

            <!-- Limits -->
            <max_linear_acceleration>5</max_linear_acceleration>
            <min_linear_acceleration>-5</min_linear_acceleration>
            <max_angular_acceleration>4</max_angular_acceleration>
            <min_angular_acceleration>-4</min_angular_acceleration>

            <max_linear_velocity>5.0</max_linear_velocity>
            <min_linear_velocity>-5.0</min_linear_velocity>
            <max_angular_velocity>4.0</max_angular_velocity>
            <min_angular_velocity>-4.0</min_angular_velocity>
            <!-- Output -->
            <frame_id>odom</frame_id>
            <child_frame_id>${namespace}base_link</child_frame_id>

            <!-- Topics -->
            <topic>/cmd_vel</topic>
            <odom_topic>/odom</odom_topic>
            <tf_topic>/tf</tf_topic>
            <odom_publisher_frequency>30</odom_publisher_frequency>
        </plugin>

        <plugin filename="ignition-gazebo-joint-state-publisher-system" name="ignition::gazebo::systems::JointStatePublisher">
            <topic>/joint_states</topic>
        </plugin>
    </gazebo>

    <gazebo reference="${namespace}wheel_right_link">
        <mu1 value="200.0" />
        <mu2 value="200.0" />
        <kp  value="1000000.0" />
        <kd  value="1.0" />
        <minDepth>0.005</minDepth>
    </gazebo>
    <gazebo reference="${namespace}wheel_left_link">
        <mu1 value="200.0" />
        <mu2 value="200.0" />
        <kp  value="1000000.0" />
        <kd  value="1.0" />
        <minDepth>0.005</minDepth>
    </gazebo>
    <gazebo reference="${namespace}base_scan">
        <sensor name='gpu_lidar' type='gpu_lidar'>
            <pose>0 0 0 0 0 0</pose>
            <topic>scan</topic>
            <!-- <ignition_frame_id>lidar_link</ignition_frame_id> -->
            <frame_name>${namespace}base_scan</frame_name>
            <gz_frame_id>${namespace}base_scan</gz_frame_id>
            <update_rate>2</update_rate>
            <lidar>
                <scan>
                <horizontal>
                    <samples>720</samples>
                    <resolution>1</resolution>
                    <min_angle>-3.14159</min_angle>
                    <max_angle>3.14159</max_angle>
                </horizontal>
                <vertical>
                    <samples>1</samples>
                    <resolution>1</resolution>
                    <min_angle>0.0</min_angle>
                    <max_angle>0.0</max_angle>
                </vertical>
                </scan>
                <range>
                    <min>0.05</min>
                    <max>10.0</max>
                    <resolution>0.01</resolution>
                </range>
                <noise>
                    <type>gaussian</type>
                    <mean>0.0</mean>
                    <stddev>0.001</stddev>
                </noise>
            </lidar>
            <always_on>true</always_on>
            <visualize>true</visualize>
        </sensor>
    </gazebo>

    <gazebo>    
        <plugin filename="gz-sim-sensors-system" name="gz::sim::systems::Sensors">
            <render_engine>ogre2</render_engine>
        </plugin>
    </gazebo>
</robot>
